Workbook
Name __R: '[2]YM Tranche 2'!$F$7
Name _2484_1_00: "Project_number"
Name a: '[3]Cash Flow'!$A$14:$W$194
Name a: '[3]Cash Flow'!$A$14:$W$194
Name Button_1: "CalifornianCasa_UnitDetails_List"
Name Button_80: "The_Bonavista_UnitDetails_List"
Name CashFlow: '[5]Cash Flow'!$A$14:$W$194
Name CashFlow: '[5]Cash Flow'!$A$14:$W$194
Name chart_balance: OFFSET(#REF!,2,0,#REF!,1)
Name chart_date: OFFSET(#REF!,2,0,#REF!,1)
Name chart_date1: OFFSET(#REF!,2,0,#REF!,1)
Name Chart1: [6]MADRONA!$M$4
Name Chart1: [6]MADRONA!$M$4
Name Chart2: [6]MADRONA!$N$2
Name Chart2: [6]MADRONA!$N$2
Name compound_period: INDEX({2,12,4,1},MATCH(#REF!,Summary!compound_periods,0))
Name compound_period: INDEX({2,12,4,1},MATCH(#REF!,[0]!compound_periods,0))
Name compound_periods: {"Semi-Annually";"Monthly";"Quarterly";"Annually"}
Name compound_periods: {"Semi-Annually";"Monthly";"Quarterly";"Annually"}
Name data: '[7]download realigned'!$A$1:$Y$12683
Name DEBT: '[8]Senior Mortgage'!$A$12:$F$32
Name DEBT: '[8]Senior Mortgage'!$A$12:$F$32
Name FlatRentRoll: [9]WAVG!$A$7:$J$65536
Name FlatRentRoll: [9]WAVG!$A$7:$J$65536
Name frequency: {"Annually";"Semi-Annually";"Quarterly";"Bi-Monthly";"Monthly";"Semi-Monthly";"Bi-Weekly";"Weekly"}
Name frequency: {"Annually";"Semi-Annually";"Quarterly";"Bi-Monthly";"Monthly";"Semi-Monthly";"Bi-Weekly";"Weekly"}
Name fuck: [6]MADRONA!$B$68:$B$73
Name fuck: [6]MADRONA!$B$68:$B$73
Name fuckyou: [6]MADRONA!$B$24:$Q$54
Name fuckyou: [6]MADRONA!$B$24:$Q$54
Name h: [6]MADRONA!$B$94:$C$153
Name h: [6]MADRONA!$B$94:$C$153
Name ImportName: [5]Summary!$C$7
Name ImportName: [5]Summary!$C$7
Name IrrLookupRange: '[5]Financing CF '!$F$7:$AB$49
Name IrrLookupRange: '[5]Financing CF '!$F$7:$AB$49
Name Maxs: 'Int Reserve - A-B Loan'!$I$24:$I$29
Name Maxs: 'Int Reserve - Single Loan'!$V$24:$V$29
Name Maxs2: 'Int Reserve - A-B Loan'!$R$24:$R$29
Name Maxs2: 'Int Reserve - Single Loan'!$I$24:$I$29
Name Mins: 'Int Reserve - A-B Loan'!$H$24:$H$29
Name Mins: 'Int Reserve - Single Loan'!$U$24:$U$29
Name Mins2: 'Int Reserve - A-B Loan'!$Q$24:$Q$29
Name Mins2: 'Int Reserve - Single Loan'!$H$24:$H$29
Name months_per_period: INDEX({12,6,3,2,1,0.5,0.5,0.25},MATCH(#REF!,Summary!frequency,0))
Name months_per_period: INDEX({12,6,3,2,1,0.5,0.5,0.25},MATCH(#REF!,frequency,0))
Name nio: '[10]Globa Ass''ns'!$J$8
Name nio: '[10]Globa Ass''ns'!$J$8
Name periods_per_year: INDEX({1,2,4,6,12,24,26,52},MATCH(#REF!,Summary!frequency,0))
Name periods_per_year: INDEX({1,2,4,6,12,24,26,52},MATCH(#REF!,frequency,0))
Name Pivot: "Rollover!$A$1:$G$10"
Name Rates: 'Int Reserve - A-B Loan'!$J$24:$J$29
Name Rates: 'Int Reserve - Single Loan'!$W$24:$W$29
Name Rates2: 'Int Reserve - A-B Loan'!$S$24:$S$29
Name Rates2: 'Int Reserve - Single Loan'!$J$24:$J$29
Name REFI: '[8]Senior Mortgage'!$AT$5:$AV$304
Name REFI: '[8]Senior Mortgage'!$AT$5:$AV$304
Name Table2: '[8]Senior Mortgage'!$AE$5:$AK$304
Name Table2: '[8]Senior Mortgage'!$AE$5:$AK$304
Name Table3: '[8]Senior Mortgage'!$AE$5:$AK$304

Sheet Summary
B2: Loan Summary | M2: CCS Approval Authority
B4: Location | F4: <Google Maps Link> | M4: David Lyons / Lujane Abdelgadir | N4: On Vacation? | O4: No
B5: Connect | F5: <Connect Link> | M5: Antoni Kajetanowicz | N5: On Vacation? | O5: No
B6: Target Funding | F6: <Date> | M6: Scott Coates | N6: On Vacation? | O6: No
B7: Type | C7: Loan Purpose | D7: <Select> | N7: Approvers Delegated (only if on vacation)? | O7: <Select>
C8: Housing | D8: =Economics!F203 -> <Housing Type> | N8: Gross Loan > $50M? | O8: =+IF(Economics!I64>50000000,"Yes","No") -> #N/A
C9: Program | D9: =Economics!F204 -> <Program> | N9: Gross Loan / Res Value > 90% (> 75% in AB & NS)? | O9: =+IF(AND(OR(Economics!F201=ControlBackEnd!C7,Economics!F201=ControlBackEnd!C6),Economics!I64/Economics!H34>0.75),"Yes",IF(Economics!I64/Economics!H34>0.9,"Yes","No")) -> #N/A
B10: Points | C10: Affordability | D10: =Economics!F217 -> 0 | N10: Retirement Home? | O10: =+IF(Economics!F203=ControlBackEnd!C13,"Yes","No") -> No
C11: Accessibility | D11: =Economics!F219 -> 0 | N11: Student Housing? | O11: =+IF(Economics!F203=ControlBackEnd!C11,"Yes","No") -> No
C12: Energy | D12: =Economics!F218 -> 0 | N12: Leased Land? | O12: <Select>
B13: Loan | C13: Gross Amount | D13: =+Economics!I64 -> #N/A | N13: Market with Population < 50,000? | O13: <Select> | P13: Click the Red Circle for Markets (use your judgement) and reference the Blue Circle for Population
C14: Term | D14: =+Economics!I68 -> 0 | N14: Request for approval of a subordinate debt? | O14: No
C15: Amortization | D15: =Economics!I69 -> 0 | M15: Rob Kumer | N15: Gross Loan > $50M? | O15: =+IF(Economics!I64>50000000,"Yes","No") -> #N/A
B16: Sponsor | C16: Name | D16: <Sponsor> | F16: <Link to company website>
C17: Experience | D17: <Select> | F17: <Very brief summary, note any concerns> | M17: CCS Approvers
C18: Guarantee | D18: <Select> | F18: <Note any concerns> | M18: David Lyons | N18: =+IF(O4="Yes","No","Yes") -> Yes
C19: CANLII Search | D19: <Completed?> | F19: <Note any concerns> | M19: Antoni Kajetanowicz | N19: =+IF(O5="Yes","No","Yes") -> Yes
C20: Net Worth | D20: <Reported NW> | F20: <Note any concerns> | M20: Scott Coates | N20: =+IF(O6="Yes","No",IF(COUNTIFS(O8:O14,"Yes")+COUNTIFS(O4:O5,"Yes")>0,"Yes","No")) -> No | O20: cc Scott in Adobe Sign for all CCS he is not approving
B21: UW Notes | C21: Gross LTV | D21: =Economics!I80 -> #N/A | F21: <Note any concerns> | M21: Rob Kumer | N21: =+IF(O15="Yes","Yes",IF(AND(O6="Yes",O7="No",COUNTIFS(O8:O13,"Yes")+COUNTIFS(O4:O5,"Yes")>0),"Yes","No")) -> #N/A
C22: Gross Loan / Res Value | D22: =+Economics!I64/Economics!H34 -> #N/A | F22: <Note any concerns>
C23: Value / Unit | D23: =Economics!I34 -> #DIV/0! | F23: =+Economics!G34 -> 0 | G23: <Note any concerns; based on what cap rate (speak to cap rate stress)>
C24: Net DSC (@ Max Rate) | D24: =Economics!H84 -> #NUM! | F24: <Note any concerns; if below minimum, why?>
C25: Max Rate / Buydown | D25: =IF(AND(Economics!I68=5,Economics!J72=0),TEXT(Economics!I71,"0.00%")&" / "&"NIL",IF(AND(Economics!I68=10,Economics!J73=0),TEXT(Economics!I71,"0.00%")&" / "&"NIL",IF(Economics!I68=5,TEXT(Economics!I71,"0.00%")&" / "&TEXT(Economics!J72,"$#,#"),TEXT(Economics!I71,"0.00%")&" / "&TEXT(Economics!J73,"$#,#")))) -> #N/A | F25: <Note any concerns>
C26: Equity | D26: =+Economics!H54-Economics!I64 -> #N/A | F26: <Discuss with Antoni and Brian if below $250k>
C27: Actual Vacancy | D27: =+Economics!AQ18 -> - | F27: <EGI Test?> | G27: <Note any concerns; lease up / separate res & commercial EGI test?>
B28: Key Risks | F28: <Note primary risks with deal>
B30: 5yr Pricing
B32: Loan Spread | D32: 0 | F32: Net Spread | G32: KS Return ($) | H32: KS Return (%) | I32: KS Margin
B33: Broker Spread | D33: 0 | F33: =F34-1 -> -4 | G33: =ROUND('Buydown Calc'!$D$6*I33/10000*$D$13+$D$36*$D$13/10000,-3) -> #N/A | H33: =G33/$D$13 -> #N/A | I33: =+(F33-$D$33-$D$34-$D$35) -> #N/A
B34: Servicing Spread | D34: {=+INDEX(ControlBackEnd!$H$3:$H$8,_xlfn.XMATCH(Summary!$D$13,ControlBackEnd!$G$3:$G$8,-1))} -> #N/A | F34: =F35-1 -> -3 | G34: =ROUND('Buydown Calc'!$D$6*I34/10000*$D$13+$D$36*$D$13/10000,-3) -> #N/A | H34: =G34/$D$13 -> #N/A | I34: =+(F34-$D$33-$D$34-$D$35) -> #N/A
B35: Agg Spread | D35: 0 | F35: =F36-1 -> -2 | G35: =ROUND('Buydown Calc'!$D$6*I35/10000*$D$13+$D$36*$D$13/10000,-3) -> #N/A | H35: =G35/$D$13 -> #N/A | I35: =+(F35-$D$33-$D$34-$D$35) -> #N/A
B36: Lender Fee | D36: 0 | F36: =F37-1 -> -1 | G36: =ROUND('Buydown Calc'!$D$6*I36/10000*$D$13+$D$36*$D$13/10000,-3) -> #N/A | H36: =G36/$D$13 -> #N/A | I36: =+(F36-$D$33-$D$34-$D$35) -> #N/A
F37: =+D32-D33 -> 0 | G37: =ROUND('Buydown Calc'!$D$6*I37/10000*$D$13+$D$36*$D$13/10000,-3) -> #N/A | H37: =G37/$D$13 -> #N/A | I37: =+(F37-$D$33-$D$34-$D$35) -> #N/A
F38: =F37+1 -> 1 | G38: =ROUND('Buydown Calc'!$D$6*I38/10000*$D$13+$D$36*$D$13/10000,-3) -> #N/A | H38: =G38/$D$13 -> #N/A | I38: =+(F38-$D$33-$D$34-$D$35) -> #N/A
F39: =F38+1 -> 2 | G39: =ROUND('Buydown Calc'!$D$6*I39/10000*$D$13+$D$36*$D$13/10000,-3) -> #N/A | H39: =G39/$D$13 -> #N/A | I39: =+(F39-$D$33-$D$34-$D$35) -> #N/A
F40: =F39+1 -> 3 | G40: =ROUND('Buydown Calc'!$D$6*I40/10000*$D$13+$D$36*$D$13/10000,-3) -> #N/A | H40: =G40/$D$13 -> #N/A | I40: =+(F40-$D$33-$D$34-$D$35) -> #N/A
F41: =F40+1 -> 4 | G41: =ROUND('Buydown Calc'!$D$6*I41/10000*$D$13+$D$36*$D$13/10000,-3) -> #N/A | H41: =G41/$D$13 -> #N/A | I41: =+(F41-$D$33-$D$34-$D$35) -> #N/A
B43: 10yr Pricing
B45: Loan Spread | D45: 0 | F45: Net Spread | G45: KS Return ($) | H45: KS Return (%) | I45: KS Margin
B46: Broker Spread | D46: 0 | F46: =F47-1 -> -4 | G46: =ROUND('Buydown Calc'!$D$7*I46/10000*$D$13+$D$49*$D$13/10000,-3) -> #N/A | H46: =G46/$D$13 -> #N/A | I46: =+(F46-$D$46-$D$47-$D$48) -> #N/A
...

Sheet Economics
C2: KingSett CMHC | L2: Underwriting Comments | N2: KingSett Bridge | W2: CMHC Benchmarks | AA2: Borrower | AD2: Variance
H3: KingSett CMHC | S3: KingSett Bridge | W3: CMHC Benchmarks | AA3: Borrower
E4: Occupied | F4: Units | G4: Size | H4: Total | I4: Per Unit | J4: PSF | P4: Occupied | Q4: Units | R4: Size | S4: Total | T4: Per Unit | U4: PSF | W4: Total | X4: /Unit | Y4: %EGI | AA4: Total | AB4: /Unit | AD4: Total | AE4: /Unit | AF4: %Delta | AI4: CMHC Avg | AJ4: CCS Delta
C5: Bachelor | E5: =+IF($F$200="Construction Financing",'Rent Roll'!G16,'Rent Roll'!G3) -> 0 | F5: =+IF($F$200="Construction Financing",'Rent Roll'!H16,'Rent Roll'!H3) -> 0 | G5: =+IF($F$200="Construction Financing",'Rent Roll'!I16,'Rent Roll'!I3) -> - | H5: =+IF($F$200="Construction Financing",'Rent Roll'!J16,'Rent Roll'!J3) -> 0 | I5: =+IF($F$200="Construction Financing",'Rent Roll'!K16,'Rent Roll'!K3) -> - | J5: =IFERROR(I5/G5,"") | N5: =C5 -> Bachelor | P5: =+E5 -> 0 | Q5: =+F5 -> 0 | R5: =+G5 -> - | S5: =+H5 -> 0 | T5: =+I5 -> - | U5: =IFERROR(T5/R5,"") | W5: =X5*F5*12 -> 0 | AA5: =AB5*F5*12 -> 0 | AD5: =HLOOKUP($AE$36,$H$3:$AA$33,ROW()-2,FALSE)-HLOOKUP($AE$35,$H$3:$AA$33,ROW()-2,FALSE) -> #N/A | AE5: =IFERROR(AD5/F5/12,"") | AF5: =IFERROR(AD5/HLOOKUP($AE$35,$H$3:$AA$33,3,FALSE),"") | AH5: see cell AI:199 for table for CCS | AJ5: =IFERROR(IF(ISBLANK(AI5),"-",+I5-AI5),"-") -> -
C6: 1 Bedroom | E6: =+IF($F$200="Construction Financing",'Rent Roll'!G17,'Rent Roll'!G4) -> 0 | F6: =+IF($F$200="Construction Financing",'Rent Roll'!H17,'Rent Roll'!H4) -> 0 | G6: =+IF($F$200="Construction Financing",'Rent Roll'!I17,'Rent Roll'!I4) -> - | H6: =+IF($F$200="Construction Financing",'Rent Roll'!J17,'Rent Roll'!J4) -> 0 | I6: =+IF($F$200="Construction Financing",'Rent Roll'!K17,'Rent Roll'!K4) -> - | J6: =IFERROR(I6/G6,"") | N6: =C6 -> 1 Bedroom | P6: =+E6 -> 0 | Q6: =+F6 -> 0 | R6: =+G6 -> - | S6: =+H6 -> 0 | T6: =+I6 -> - | U6: =IFERROR(T6/R6,"") | W6: =X6*F6*12 -> 0 | AA6: =AB6*F6*12 -> 0 | AD6: =HLOOKUP($AE$36,$H$3:$AA$33,ROW()-2,FALSE)-HLOOKUP($AE$35,$H$3:$AA$33,ROW()-2,FALSE) -> #N/A | AE6: =IFERROR(AD6/F6/12,"") | AF6: =IFERROR(AD6/HLOOKUP($AE$35,$H$3:$AA$33,4,FALSE),"") | AJ6: =IFERROR(IF(ISBLANK(AI6),"-",+I6-AI6),"-") -> -
C7: 2 Bedroom | E7: =+IF($F$200="Construction Financing",'Rent Roll'!G18,'Rent Roll'!G5) -> 0 | F7: =+IF($F$200="Construction Financing",'Rent Roll'!H18,'Rent Roll'!H5) -> 0 | G7: =+IF($F$200="Construction Financing",'Rent Roll'!I18,'Rent Roll'!I5) -> - | H7: =+IF($F$200="Construction Financing",'Rent Roll'!J18,'Rent Roll'!J5) -> 0 | I7: =+IF($F$200="Construction Financing",'Rent Roll'!K18,'Rent Roll'!K5) -> - | J7: =IFERROR(I7/G7,"") | N7: =C7 -> 2 Bedroom | P7: =+E7 -> 0 | Q7: =+F7 -> 0 | R7: =+G7 -> - | S7: =+H7 -> 0 | T7: =+I7 -> - | U7: =IFERROR(T7/R7,"") | W7: =X7*F7*12 -> 0 | AA7: =AB7*F7*12 -> 0 | AD7: =HLOOKUP($AE$36,$H$3:$AA$33,ROW()-2,FALSE)-HLOOKUP($AE$35,$H$3:$AA$33,ROW()-2,FALSE) -> #N/A | AE7: =IFERROR(AD7/F7/12,"") | AF7: =IFERROR(AD7/HLOOKUP($AE$35,$H$3:$AA$33,5,FALSE),"") | AJ7: =IFERROR(IF(ISBLANK(AI7),"-",+I7-AI7),"-") -> -
C8: 3 Bedroom | E8: =+IF($F$200="Construction Financing",'Rent Roll'!G19,'Rent Roll'!G6) -> 0 | F8: =+IF($F$200="Construction Financing",'Rent Roll'!H19,'Rent Roll'!H6) -> 0 | G8: =+IF($F$200="Construction Financing",'Rent Roll'!I19,'Rent Roll'!I6) -> - | H8: =+IF($F$200="Construction Financing",'Rent Roll'!J19,'Rent Roll'!J6) -> 0 | I8: =+IF($F$200="Construction Financing",'Rent Roll'!K19,'Rent Roll'!K6) -> - | J8: =IFERROR(I8/G8,"") | N8: =C8 -> 3 Bedroom | P8: =+E8 -> 0 | Q8: =+F8 -> 0 | R8: =+G8 -> - | S8: =+H8 -> 0 | T8: =+I8 -> - | U8: =IFERROR(T8/R8,"") | W8: =X8*F8*12 -> 0 | AA8: =AB8*F8*12 -> 0 | AD8: =HLOOKUP($AE$36,$H$3:$AA$33,ROW()-2,FALSE)-HLOOKUP($AE$35,$H$3:$AA$33,ROW()-2,FALSE) -> #N/A | AE8: =IFERROR(AD8/F8/12,"") | AF8: =IFERROR(AD8/HLOOKUP($AE$35,$H$3:$AA$33,6,FALSE),"") | AJ8: =IFERROR(IF(ISBLANK(AI8),"-",+I8-AI8),"-") -> -
C9: 4+ Bedroom | E9: =+IF($F$200="Construction Financing",'Rent Roll'!G20,'Rent Roll'!G7) -> 0 | F9: =+IF($F$200="Construction Financing",'Rent Roll'!H20,'Rent Roll'!H7) -> 0 | G9: =+IF($F$200="Construction Financing",'Rent Roll'!I20,'Rent Roll'!I7) -> - | H9: =+IF($F$200="Construction Financing",'Rent Roll'!J20,'Rent Roll'!J7) -> 0 | I9: =+IF($F$200="Construction Financing",'Rent Roll'!K20,'Rent Roll'!K7) -> - | J9: =IFERROR(I9/G9,"") | N9: =C9 -> 4+ Bedroom | P9: =+E9 -> 0 | Q9: =+F9 -> 0 | R9: =+G9 -> - | S9: =+H9 -> 0 | T9: =+I9 -> - | U9: =IFERROR(T9/R9,"") | W9: =X9*F9*12 -> 0 | AA9: =AB9*F9*12 -> 0 | AD9: =HLOOKUP($AE$36,$H$3:$AA$33,ROW()-2,FALSE)-HLOOKUP($AE$35,$H$3:$AA$33,ROW()-2,FALSE) -> #N/A | AE9: =IFERROR(AD9/F9/12,"") | AF9: =IFERROR(AD9/HLOOKUP($AE$35,$H$3:$AA$33,7,FALSE),"") | AJ9: =IFERROR(IF(ISBLANK(AI9),"-",+I9-AI9),"-") -> -
C10: Bachelor (Affordable) | E10: =+IF($F$200="Construction Financing",'Rent Roll'!G21,'Rent Roll'!G8) -> 0 | F10: =+IF($F$200="Construction Financing",'Rent Roll'!H21,'Rent Roll'!H8) -> 0 | G10: =+IF($F$200="Construction Financing",'Rent Roll'!I21,'Rent Roll'!I8) -> - | H10: =+IF($F$200="Construction Financing",'Rent Roll'!J21,'Rent Roll'!J8) -> 0 | I10: =+IF($F$200="Construction Financing",'Rent Roll'!K21,'Rent Roll'!K8) -> - | J10: =IFERROR(I10/G10,"") | N10: =C10 -> Bachelor (Affordable) | P10: =+E10 -> 0 | Q10: =+F10 -> 0 | R10: =+G10 -> - | S10: =+H10 -> 0 | T10: =+I10 -> - | U10: =IFERROR(T10/R10,"") | W10: =X10*F10*12 -> 0 | AA10: =AB10*F10*12 -> 0 | AD10: =HLOOKUP($AE$36,$H$3:$AA$33,ROW()-2,FALSE)-HLOOKUP($AE$35,$H$3:$AA$33,ROW()-2,FALSE) -> #N/A | AE10: =IFERROR(AD10/F10/12,"") | AF10: =IFERROR(AD10/HLOOKUP($AE$35,$H$3:$AA$33,8,FALSE),"") | AJ10: =IFERROR(IF(ISBLANK(AI10),"-",+I10-AI10),"-") -> -
C11: 1 Bedroom (Affordable) | E11: =+IF($F$200="Construction Financing",'Rent Roll'!G22,'Rent Roll'!G9) -> 0 | F11: =+IF($F$200="Construction Financing",'Rent Roll'!H22,'Rent Roll'!H9) -> 0 | G11: =+IF($F$200="Construction Financing",'Rent Roll'!I22,'Rent Roll'!I9) -> - | H11: =+IF($F$200="Construction Financing",'Rent Roll'!J22,'Rent Roll'!J9) -> 0 | I11: =+IF($F$200="Construction Financing",'Rent Roll'!K22,'Rent Roll'!K9) -> - | J11: =IFERROR(I11/G11,"") | N11: =C11 -> 1 Bedroom (Affordable) | P11: =+E11 -> 0 | Q11: =+F11 -> 0 | R11: =+G11 -> - | S11: =+H11 -> 0 | T11: =+I11 -> - | U11: =IFERROR(T11/R11,"") | W11: =X11*F11*12 -> 0 | AA11: =AB11*F11*12 -> 0 | AD11: =HLOOKUP($AE$36,$H$3:$AA$33,ROW()-2,FALSE)-HLOOKUP($AE$35,$H$3:$AA$33,ROW()-2,FALSE) -> #N/A | AE11: =IFERROR(AD11/F11/12,"") | AF11: =IFERROR(AD11/HLOOKUP($AE$35,$H$3:$AA$33,9,FALSE),"") | AJ11: =IFERROR(IF(ISBLANK(AI11),"-",+I11-AI11),"-") -> -
C12: 2 Bedroom (Affordable) | E12: =+IF($F$200="Construction Financing",'Rent Roll'!G23,'Rent Roll'!G10) -> 0 | F12: =+IF($F$200="Construction Financing",'Rent Roll'!H23,'Rent Roll'!H10) -> 0 | G12: =+IF($F$200="Construction Financing",'Rent Roll'!I23,'Rent Roll'!I10) -> - | H12: =+IF($F$200="Construction Financing",'Rent Roll'!J23,'Rent Roll'!J10) -> 0 | I12: =+IF($F$200="Construction Financing",'Rent Roll'!K23,'Rent Roll'!K10) -> - | J12: =IFERROR(I12/G12,"") | N12: =C12 -> 2 Bedroom (Affordable) | P12: =+E12 -> 0 | Q12: =+F12 -> 0 | R12: =+G12 -> - | S12: =+H12 -> 0 | T12: =+I12 -> - | U12: =IFERROR(T12/R12,"") | W12: =X12*F12*12 -> 0 | AA12: =AB12*F12*12 -> 0 | AD12: =HLOOKUP($AE$36,$H$3:$AA$33,ROW()-2,FALSE)-HLOOKUP($AE$35,$H$3:$AA$33,ROW()-2,FALSE) -> #N/A | AE12: =IFERROR(AD12/F12/12,"") | AF12: =IFERROR(AD12/HLOOKUP($AE$35,$H$3:$AA$33,10,FALSE),"") | AJ12: =IFERROR(IF(ISBLANK(AI12),"-",+I12-AI12),"-") -> -
C13: 3 Bedroom (Affordable) | E13: =+IF($F$200="Construction Financing",'Rent Roll'!G24,'Rent Roll'!G11) -> 0 | F13: =+IF($F$200="Construction Financing",'Rent Roll'!H24,'Rent Roll'!H11) -> 0 | G13: =+IF($F$200="Construction Financing",'Rent Roll'!I24,'Rent Roll'!I11) -> - | H13: =+IF($F$200="Construction Financing",'Rent Roll'!J24,'Rent Roll'!J11) -> 0 | I13: =+IF($F$200="Construction Financing",'Rent Roll'!K24,'Rent Roll'!K11) -> - | J13: =IFERROR(I13/G13,"") | N13: =C13 -> 3 Bedroom (Affordable) | P13: =+E13 -> 0 | Q13: =+F13 -> 0 | R13: =+G13 -> - | S13: =+H13 -> 0 | T13: =+I13 -> - | U13: =IFERROR(T13/R13,"") | W13: =X13*F13*12 -> 0 | AA13: =AB13*F13*12 -> 0 | AD13: =HLOOKUP($AE$36,$H$3:$AA$33,ROW()-2,FALSE)-HLOOKUP($AE$35,$H$3:$AA$33,ROW()-2,FALSE) -> #N/A | AE13: =IFERROR(AD13/F13/12,"") | AF13: =IFERROR(AD13/HLOOKUP($AE$35,$H$3:$AA$33,11,FALSE),"") | AJ13: =IFERROR(IF(ISBLANK(AI13),"-",+I13-AI13),"-") -> -
C14: 4+ Bedroom (Affordable) | E14: =+IF($F$200="Construction Financing",'Rent Roll'!G25,'Rent Roll'!G12) -> 0 | F14: =+IF($F$200="Construction Financing",'Rent Roll'!H25,'Rent Roll'!H12) -> 0 | G14: =+IF($F$200="Construction Financing",'Rent Roll'!I25,'Rent Roll'!I12) -> - | H14: =+IF($F$200="Construction Financing",'Rent Roll'!J25,'Rent Roll'!J12) -> 0 | I14: =+IF($F$200="Construction Financing",'Rent Roll'!K25,'Rent Roll'!K12) -> - | J14: =IFERROR(I14/G14,"") | N14: =C14 -> 4+ Bedroom (Affordable) | P14: =+E14 -> 0 | Q14: =+F14 -> 0 | R14: =+G14 -> - | S14: =+H14 -> 0 | T14: =+I14 -> - | U14: =IFERROR(T14/R14,"") | W14: =X14*F14*12 -> 0 | AA14: =AB14*F14*12 -> 0 | AD14: =HLOOKUP($AE$36,$H$3:$AA$33,ROW()-2,FALSE)-HLOOKUP($AE$35,$H$3:$AA$33,ROW()-2,FALSE) -> #N/A | AE14: =IFERROR(AD14/F14/12,"") | AF14: =IFERROR(AD14/HLOOKUP($AE$35,$H$3:$AA$33,12,FALSE),"") | AJ14: =IFERROR(IF(ISBLANK(AI14),"-",+I14-AI14),"-") -> -
C15: Total Rental Income | E15: =+SUM(E5:E14) -> 0 | F15: =+SUM(F5:F14) -> 0 | G15: =IF(SUMPRODUCT(F5:F14,G5:G14)/F15=0,"-",SUMPRODUCT(F5:F14,G5:G14)/F15) -> #DIV/0! | H15: =+SUM(H5:H14) -> 0 | I15: =H15/F15/12 -> #DIV/0! | J15: =IFERROR(I15/G15,"N/A") -> N/A | N15: Total Rental Income | P15: =+SUM(P5:P14) -> 0 | Q15: =+SUM(Q5:Q14) -> 0 | R15: =IF(SUMPRODUCT(Q5:Q14,R5:R14)/Q15=0,"-",SUMPRODUCT(Q5:Q14,R5:R14)/Q15) -> #DIV/0! | S15: =+SUM(S5:S14) -> 0 | T15: =S15/Q15/12 -> #DIV/0! | U15: =IFERROR(I15/G15,"N/A") -> N/A | W15: =SUBTOTAL(9,W4:W14) -> 0 | X15: =W15/F15/12 -> #DIV/0! | AA15: =SUBTOTAL(9,AA5:AA14) -> 0 | AB15: =AA15/$F$15/12 -> #DIV/0! | AD15: =HLOOKUP($AE$36,$H$3:$AA$33,ROW()-2,FALSE)-HLOOKUP($AE$35,$H$3:$AA$33,ROW()-2,FALSE) -> #N/A | AE15: =AD15/$F$15 -> #N/A | AF15: =IFERROR(AD15/HLOOKUP($AE$35,$H$3:$AA$33,13,FALSE),"")
C16: (+) UG Parking | E16: 1 | F16: 0 | G16: 0 | H16: =F16*E16*(G16*12) -> 0 | N16: (+) UG Parking | P16: =+E16 -> 1 | Q16: =+F16 -> 0 | R16: =+G16 -> 0 | S16: =Q16*P16*(R16*12) -> 0 | AD16: =HLOOKUP($AE$36,$H$3:$AA$33,ROW()-2,FALSE)-HLOOKUP($AE$35,$H$3:$AA$33,ROW()-2,FALSE) -> #N/A | AE16: =AD16/$F$15 -> #N/A | AF16: =IFERROR(AD16/HLOOKUP($AE$35,$H$3:$AA$33,15,FALSE),"")
C17: (+) EX Parking | E17: 1 | F17: 0 | G17: 0 | H17: =F17*E17*(G17*12) -> 0 | N17: (+) EX Parking | P17: =+E17 -> 1 | Q17: =+F17 -> 0 | R17: =+G17 -> 0 | S17: =Q17*P17*(R17*12) -> 0 | AD17: =HLOOKUP($AE$36,$H$3:$AA$33,ROW()-2,FALSE)-HLOOKUP($AE$35,$H$3:$AA$33,ROW()-2,FALSE) -> #N/A | AE17: =AD17/$F$15 -> #N/A | AF17: =IFERROR(AD17/HLOOKUP($AE$35,$H$3:$AA$33,16,FALSE),"") | AJ17: CMHC Zone | AK17: 2023 | AL17: =AK17-1 -> 2022 | AM17: =AL17-1 -> 2021 | AN17: =AM17-1 -> 2020 | AO17: =AN17-1 -> 2019 | AP17: 5Y Avg | AQ17: Subject Vacancy
C18: (+) Storage | E18: 1 | F18: 0 | G18: 0 | H18: =F18*E18*(G18*12) -> 0 | N18: (+) Storage | P18: =+E18 -> 1 | Q18: =+F18 -> 0 | R18: =+G18 -> 0 | S18: =Q18*P18*(R18*12) -> 0 | AD18: =HLOOKUP($AE$36,$H$3:$AA$33,ROW()-2,FALSE)-HLOOKUP($AE$35,$H$3:$AA$33,ROW()-2,FALSE) -> #N/A | AE18: =AD18/$F$15 -> #N/A | AF18: =IFERROR(AD18/HLOOKUP($AE$35,$H$3:$AA$33,16,FALSE),"") | AI18: Vacancy | AP18: =IFERROR(AVERAGE($AK$18:$AO$18),"-") -> - | AQ18: =IF(F15=0,"-",1-E15/F15) -> -
C19: (+) Other | H19: 0 | I19: =H19/$F$15 -> #DIV/0! | N19: (+) Other | S19: =+H19 -> 0 | T19: =S19/$F$15 -> #DIV/0! | AD19: =HLOOKUP($AE$36,$H$3:$AA$33,ROW()-2,FALSE)-HLOOKUP($AE$35,$H$3:$AA$33,ROW()-2,FALSE) -> #N/A | AE19: =AD19/$F$15 -> #N/A | AF19: =IFERROR(AD19/HLOOKUP($AE$35,$H$3:$AA$33,16,FALSE),"") | AI19: Rent YoY Change | AP19: =IFERROR(AVERAGE($AK$19:$AO$19),"-") -> -
C20: (-) Incentives | H20: 0 | I20: =H20/$F$15 -> #DIV/0! | N20: (-) Incentives | S20: =+H20 -> 0 | T20: =S20/$F$15 -> #DIV/0! | AD20: =HLOOKUP($AE$36,$H$3:$AA$33,ROW()-2,FALSE)-HLOOKUP($AE$35,$H$3:$AA$33,ROW()-2,FALSE) -> #N/A | AE20: =AD20/$F$15 -> #N/A | AF20: =IFERROR(AD20/HLOOKUP($AE$35,$H$3:$AA$33,16,FALSE),"")
C21: Potential Gross Income | H21: =+SUM(H15:H20) -> 0 | I21: =H21/F15/12 -> #DIV/0! | N21: Potential Gross Income | S21: =+SUM(S15:S20) -> 0 | T21: =S21/$Q$15/12 -> #DIV/0! | AA21: =SUBTOTAL(9,AA4:AA18) -> 0 | AB21: =AA21/$F$15/12 -> #DIV/0! | AD21: =HLOOKUP($AE$36,$H$3:$AA$33,ROW()-2,FALSE)-HLOOKUP($AE$35,$H$3:$AA$33,ROW()-2,FALSE) -> #N/A | AE21: =AD21/$F$15 -> #N/A | AF21: =IFERROR(AD21/HLOOKUP($AE$35,$H$3:$AA$33,16,FALSE),"") | AI21: =+G22 -> 0
C22: (-) Vacancy/bad debt | H22: =-H21*G22 -> 0 | N22: (-) Vacancy/bad debt | R22: =+G22 -> 0 | S22: =-S21*R22 -> 0 | AD22: =HLOOKUP($AE$36,$H$3:$AA$33,ROW()-2,FALSE)-HLOOKUP($AE$35,$H$3:$AA$33,ROW()-2,FALSE) -> #N/A | AE22: =AD22/$F$15 -> #N/A | AF22: =IFERROR(AD22/HLOOKUP($AE$35,$H$3:$AA$33,19,FALSE),"")
C23: Effective Gross Income | H23: =+SUM(H21:H22) -> 0 | I23: =H23/F15/12 -> #DIV/0! | N23: Effective Gross Income | S23: =+SUM(S21:S22) -> 0 | T23: =S23/$Q$15/12 -> #DIV/0! | AA23: =SUBTOTAL(9,AA4:AA22) -> 0 | AB23: =AA23/$F$15/12 -> #DIV/0! | AD23: =HLOOKUP($AE$36,$H$3:$AA$33,ROW()-2,FALSE)-HLOOKUP($AE$35,$H$3:$AA$33,ROW()-2,FALSE) -> #N/A | AE23: =AD23/$F$15 -> #N/A | AF23: =IFERROR(AD23/HLOOKUP($AE$35,$H$3:$AA$33,20,FALSE),"") | AI23: Opex | AJ23: 2024 Bills | AK23: 2024 O/S | AL23: 2024 Appraisal | AM23: KS Estimate | AN23: <- Change source description here, if applicable
C24: =+BenchmarkBackEnd!D4 -> (-) Property Taxes | H24: =IF(G24="",MAX(AJ24:AM24),_xlfn.XLOOKUP(G24,$AJ$23:$AM$23,$AJ24:$AM24))*(1+$AJ$30) -> 0 | I24: =H24/$F$15 -> #DIV/0! | N24: =+BenchmarkBackEnd!D4 -> (-) Property Taxes | S24: =+H24 -> 0 | T24: =S24/$Q$15 -> #DIV/0! | W24: =X24*$F$15 -> 0 | X24: =SUMIFS(BenchmarkBackEnd!$E:$E,BenchmarkBackEnd!$A:$A,Economics!$F$201,BenchmarkBackEnd!$B:$B,Economics!$F$206,BenchmarkBackEnd!$C:$C,Economics!$F$210,BenchmarkBackEnd!$D:$D,Economics!$C24) -> 0 | Y24: =SUMIFS(BenchmarkBackEnd!$F:$F,BenchmarkBackEnd!$A:$A,Economics!$F$201,BenchmarkBackEnd!$B:$B,Economics!$F$206,BenchmarkBackEnd!$C:$C,Economics!$F$210,BenchmarkBackEnd!$D:$D,Economics!$C24) -> 0 | AB24: =AA24/$F$15 -> #DIV/0! | AD24: =HLOOKUP($AE$36,$H$3:$AA$33,ROW()-2,FALSE)-HLOOKUP($AE$35,$H$3:$AA$33,ROW()-2,FALSE) -> #N/A | AE24: =AD24/$F$15 -> #N/A | AF24: =IFERROR(AD24/HLOOKUP($AE$35,$H$3:$AA$33,21,FALSE),"") | AI24: Property Taxes | AJ24: 0 | AK24: 0 | AL24: 0 | AM24: 0
C25: =+BenchmarkBackEnd!D5 -> (-) Insurance | H25: =IF(G25="",MAX(AJ25:AM25),_xlfn.XLOOKUP(G25,$AJ$23:$AM$23,$AJ25:$AM25))*(1+$AJ$30) -> 0 | I25: =H25/$F$15 -> #DIV/0! | N25: =+BenchmarkBackEnd!D5 -> (-) Insurance | S25: =+H25 -> 0 | T25: =S25/$Q$15 -> #DIV/0! | W25: =X25*$F$15 -> 0 | X25: =SUMIFS(BenchmarkBackEnd!$E:$E,BenchmarkBackEnd!$A:$A,Economics!$F$201,BenchmarkBackEnd!$B:$B,Economics!$F$206,BenchmarkBackEnd!$C:$C,Economics!$F$210,BenchmarkBackEnd!$D:$D,Economics!$C25) -> 0 | Y25: =SUMIFS(BenchmarkBackEnd!$F:$F,BenchmarkBackEnd!$A:$A,Economics!$F$201,BenchmarkBackEnd!$B:$B,Economics!$F$206,BenchmarkBackEnd!$C:$C,Economics!$F$210,BenchmarkBackEnd!$D:$D,Economics!$C25) -> 0 | AB25: =AA25/$F$15 -> #DIV/0! | AD25: =HLOOKUP($AE$36,$H$3:$AA$33,ROW()-2,FALSE)-HLOOKUP($AE$35,$H$3:$AA$33,ROW()-2,FALSE) -> #N/A | AE25: =AD25/$F$15 -> #N/A | AF25: =IFERROR(AD25/HLOOKUP($AE$35,$H$3:$AA$33,22,FALSE),"") | AI25: Insurance | AJ25: 0 | AK25: 0 | AL25: 0 | AM25: 0
C26: =+BenchmarkBackEnd!D6 -> (-) Utilities | D26: Landlord pays heating & hydro | H26: =IF(G26="",MAX(AJ26:AM26),_xlfn.XLOOKUP(G26,$AJ$23:$AM$23,$AJ26:$AM26))*(1+$AJ$30) -> 0 | I26: =H26/$F$15 -> #DIV/0! | N26: =+BenchmarkBackEnd!D6 -> (-) Utilities | S26: =+H26 -> 0 | T26: =S26/$Q$15 -> #DIV/0! | W26: =X26*$F$15 -> 0 | X26: =SUMIFS(BenchmarkBackEnd!$E:$E,BenchmarkBackEnd!$A:$A,Economics!$F$201,BenchmarkBackEnd!$B:$B,Economics!$F$206,BenchmarkBackEnd!$C:$C,Economics!$F$210,BenchmarkBackEnd!$D:$D,Economics!$C26) -> 0 | Y26: =SUMIFS(BenchmarkBackEnd!$F:$F,BenchmarkBackEnd!$A:$A,Economics!$F$201,BenchmarkBackEnd!$B:$B,Economics!$F$206,BenchmarkBackEnd!$C:$C,Economics!$F$210,BenchmarkBackEnd!$D:$D,Economics!$C26) -> 0 | AB26: =AA26/$F$15 -> #DIV/0! | AD26: =HLOOKUP($AE$36,$H$3:$AA$33,ROW()-2,FALSE)-HLOOKUP($AE$35,$H$3:$AA$33,ROW()-2,FALSE) -> #N/A | AE26: =AD26/$F$15 -> #N/A | AF26: =IFERROR(AD26/HLOOKUP($AE$35,$H$3:$AA$33,23,FALSE),"") | AI26: Utilities | AJ26: =Utilities!D21 -> 0 | AK26: 0 | AL26: 0 | AM26: 0
C27: =+BenchmarkBackEnd!D7 -> (-) Repairs and Maintenance | H27: =I27*$F$15 -> 0 | I27: =X27*(1+$AK$30) -> 4675 | N27: =+BenchmarkBackEnd!D7 -> (-) Repairs and Maintenance | S27: =T27*Q15 -> 0 | T27: =+I27 -> 4675 | W27: =X27*$F$15 -> 0 | X27: =SUMIFS(BenchmarkBackEnd!$E:$E,BenchmarkBackEnd!$A:$A,Economics!$F$201,BenchmarkBackEnd!$B:$B,Economics!$F$206,BenchmarkBackEnd!$C:$C,Economics!$F$210,BenchmarkBackEnd!$D:$D,Economics!$C27) -> 4675 | Y27: =SUMIFS(BenchmarkBackEnd!$F:$F,BenchmarkBackEnd!$A:$A,Economics!$F$201,BenchmarkBackEnd!$B:$B,Economics!$F$206,BenchmarkBackEnd!$C:$C,Economics!$F$210,BenchmarkBackEnd!$D:$D,Economics!$C27) -> 0 | AB27: =AA27/$F$15 -> #DIV/0! | AD27: =HLOOKUP($AE$36,$H$3:$AA$33,ROW()-2,FALSE)-HLOOKUP($AE$35,$H$3:$AA$33,ROW()-2,FALSE) -> #N/A | AE27: =AD27/$F$15 -> #N/A | AF27: =IFERROR(AD27/HLOOKUP($AE$35,$H$3:$AA$33,24,FALSE),"")
C28: =+BenchmarkBackEnd!D8 -> (-) Payroll & Administration | H28: =I28*$F$15 -> 0 | I28: =X28*(1+$AK$30) -> 3285 | N28: =+BenchmarkBackEnd!D8 -> (-) Payroll & Administration | S28: =T28*Q15 -> 0 | T28: =+I28 -> 3285 | W28: =X28*$F$15 -> 0 | X28: =SUMIFS(BenchmarkBackEnd!$E:$E,BenchmarkBackEnd!$A:$A,Economics!$F$201,BenchmarkBackEnd!$B:$B,Economics!$F$206,BenchmarkBackEnd!$C:$C,Economics!$F$210,BenchmarkBackEnd!$D:$D,Economics!$C28) -> 3285 | Y28: =SUMIFS(BenchmarkBackEnd!$F:$F,BenchmarkBackEnd!$A:$A,Economics!$F$201,BenchmarkBackEnd!$B:$B,Economics!$F$206,BenchmarkBackEnd!$C:$C,Economics!$F$210,BenchmarkBackEnd!$D:$D,Economics!$C28) -> 0 | AB28: =AA28/$F$15 -> #DIV/0! | AD28: =HLOOKUP($AE$36,$H$3:$AA$33,ROW()-2,FALSE)-HLOOKUP($AE$35,$H$3:$AA$33,ROW()-2,FALSE) -> #N/A | AE28: =AD28/$F$15 -> #N/A | AF28: =IFERROR(AD28/HLOOKUP($AE$35,$H$3:$AA$33,25,FALSE),"") | AI28: Growth | AJ28: Annualized | AK28: Total
C29: =+BenchmarkBackEnd!D10 -> (-) Other | G29: =Y29 -> 0.061 | H29: =G29*$H$23 -> 0 | I29: =H29/$F$15 -> #DIV/0! | N29: =+BenchmarkBackEnd!D10 -> (-) Other | R29: =+G29 -> 0.061 | S29: =R29*$S$23 -> 0 | T29: =S29/$Q$15 -> #DIV/0! | W29: =X29*F15 -> 0 | X29: =SUMIFS(BenchmarkBackEnd!$E:$E,BenchmarkBackEnd!$A:$A,Economics!$F$201,BenchmarkBackEnd!$B:$B,Economics!$F$206,BenchmarkBackEnd!$C:$C,Economics!$F$210,BenchmarkBackEnd!$D:$D,Economics!$C29) -> 0 | Y29: =SUMIFS(BenchmarkBackEnd!$F:$F,BenchmarkBackEnd!$A:$A,Economics!$F$201,BenchmarkBackEnd!$B:$B,Economics!$F$206,BenchmarkBackEnd!$C:$C,Economics!$F$210,BenchmarkBackEnd!$D:$D,Economics!$C29) -> 0.061 | AB29: =AA29/$F$15 -> #DIV/0! | AD29: =HLOOKUP($AE$36,$H$3:$AA$33,ROW()-2,FALSE)-HLOOKUP($AE$35,$H$3:$AA$33,ROW()-2,FALSE) -> #N/A | AE29: =AD29/$F$15 -> #N/A | AF29: =IFERROR(AD29/HLOOKUP($AE$35,$H$3:$AA$33,26,FALSE),"") | AI29: Rent | AJ29: 0 | AK29: =$AJ$29*Economics!$I$65 -> 0
C30: =+BenchmarkBackEnd!D11 -> (-) Management Fee | G30: =Y30 -> 0.22 | H30: =G30*$H$23 -> 0 | I30: =H30/$F$15 -> #DIV/0! | N30: =+BenchmarkBackEnd!D11 -> (-) Management Fee | R30: =+G30 -> 0.22 | S30: =R30*$S$23 -> 0 | T30: =S30/$Q$15 -> #DIV/0! | W30: =X30*F15 -> 0 | X30: =SUMIFS(BenchmarkBackEnd!$E:$E,BenchmarkBackEnd!$A:$A,Economics!$F$201,BenchmarkBackEnd!$B:$B,Economics!$F$206,BenchmarkBackEnd!$C:$C,Economics!$F$210,BenchmarkBackEnd!$D:$D,Economics!$C30) -> 0 | Y30: =SUMIFS(BenchmarkBackEnd!$F:$F,BenchmarkBackEnd!$A:$A,Economics!$F$201,BenchmarkBackEnd!$B:$B,Economics!$F$206,BenchmarkBackEnd!$C:$C,Economics!$F$210,BenchmarkBackEnd!$D:$D,Economics!$C30) -> 0.22 | AB30: =AA30/$F$15 -> #DIV/0! | AD30: =HLOOKUP($AE$36,$H$3:$AA$33,ROW()-2,FALSE)-HLOOKUP($AE$35,$H$3:$AA$33,ROW()-2,FALSE) -> #N/A | AE30: =AD30/$F$15 -> #N/A | AF30: =IFERROR(AD30/HLOOKUP($AE$35,$H$3:$AA$33,27,FALSE),"") | AI30: Opex | AJ30: 0 | AK30: =$AJ$30*$I$65 -> 0
C31: =+BenchmarkBackEnd!D12 -> (-) Replacement Reserve | H31: =W31*(1+$AK$30) -> 0 | I31: =H31/$F$15 -> #DIV/0! | N31: =+BenchmarkBackEnd!D12 -> (-) Replacement Reserve | S31: =+H31 -> 0 | T31: =S31/$Q$15 -> #DIV/0! | W31: =(F214*60*F15+F215*190+F216*12*300) -> 0 | X31: =F214*60 -> 0 | AB31: =AA31/$F$15 -> #DIV/0! | AD31: =HLOOKUP($AE$36,$H$3:$AA$33,ROW()-2,FALSE)-HLOOKUP($AE$35,$H$3:$AA$33,ROW()-2,FALSE) -> #N/A | AE31: =AD31/$F$15 -> #N/A | AF31: =IFERROR(AD31/HLOOKUP($AE$35,$H$3:$AA$33,28,FALSE),"") | AI31: Apply only for construction loans
C32: Operating Expenses | G32: =H32/H23 -> #DIV/0! | H32: =+SUM(H24:H31) -> 0 | I32: =H32/$F$15 -> #DIV/0! | N32: Operating Expenses | R32: =S32/S23 -> #DIV/0! | S32: =+SUM(S24:S31) -> 0 | T32: =S32/$Q$15 -> #DIV/0! | W32: =SUM(W24:W31) -> 0 | X32: =SUMIFS(BenchmarkBackEnd!$E:$E,BenchmarkBackEnd!$A:$A,Economics!$F$201,BenchmarkBackEnd!$B:$B,Economics!$F$206,BenchmarkBackEnd!$C:$C,Economics!$F$210,BenchmarkBackEnd!$D:$D,Economics!$C32) -> 0 | Y32: =SUMIFS(BenchmarkBackEnd!$F:$F,BenchmarkBackEnd!$A:$A,Economics!$F$201,BenchmarkBackEnd!$B:$B,Economics!$F$206,BenchmarkBackEnd!$C:$C,Economics!$F$210,BenchmarkBackEnd!$D:$D,Economics!$C32) -> 0 | AA32: =SUM(AA24:AA31) -> 0 | AB32: =AA32/$F$15 -> #DIV/0! | AD32: =HLOOKUP($AE$36,$H$3:$AA$33,ROW()-2,FALSE)-HLOOKUP($AE$35,$H$3:$AA$33,ROW()-2,FALSE) -> #N/A | AE32: =AD32/$F$15 -> #N/A | AF32: =IFERROR(AD32/HLOOKUP($AE$35,$H$3:$AA$33,29,FALSE),"")
C33: NOI | H33: =+H23-H32 -> 0 | I33: =H33/$F$15 -> #DIV/0! | N33: NOI | S33: =S23-S32 -> 0 | T33: =S33/$Q$15 -> #DIV/0! | AA33: =AA23-AA32 -> 0 | AB33: =AA33/$F$15 -> #DIV/0! | AD33: =HLOOKUP($AE$36,$H$3:$AA$33,ROW()-2,FALSE)-HLOOKUP($AE$35,$H$3:$AA$33,ROW()-2,FALSE) -> #N/A | AE33: =AD33/$F$15 -> #N/A | AF33: =IFERROR(AD33/HLOOKUP($AE$35,$H$3:$AA$33,29,FALSE),"")
C34: Value | F34: UW Cap Rate: | H34: =IFERROR(ROUND(H33/G34,-4),0) -> 0 | I34: =H34/$F$15 -> #DIV/0! | J34: =IFERROR(I34/G15,"N/A") -> N/A | N34: Value | Q34: UW Cap Rate: | S34: =S33/R34 -> #DIV/0! | T34: =S34/$Q$15 -> #DIV/0! | U34: =T34/$R$15 -> #DIV/0!
N35: Less: Cost to Complete | T35: =S35/$Q$15 -> #DIV/0! | U35: =T35/$R$15 -> #DIV/0! | AD35: Base
C36: Commercial | E36: Move-In | F36: Expiry | G36: Area | H36: Total | I36: Rate | N36: Adj. Value | Q36: Ind Cap Rate: | R36: =S33/S36 -> #DIV/0! | S36: =S34-S35 -> #DIV/0! | T36: =S36/$Q$15 -> #DIV/0! | U36: =T36/$R$15 -> #DIV/0! | AD36: Comparison
C37: Tenant 1 | H37: =G37*I37 -> 0
C38: Tenant 2 | H38: =G38*I38 -> 0 | N38: Loan Details | S38: SMF | T38: MLP | U38: Blended | AI38: Bridge Guidelines
C39: Tenant 3 | H39: =G39*I39 -> 0 | N39: Loan Amount | S39: 0 | T39: =S75 -> #N/A | U39: =+S79 -> #N/A | AI39: SMF capped at 65% LTV
C40: Tenant 4 | H40: =G40*I40 -> 0 | N40: Loan Split | S40: =+S39/$U$39 -> #N/A | T40: =+T39/$U$39 -> #N/A | U40: =+SUM(S40:T40) -> #N/A | AI40: Target approx. 70% SMF/30% MLP loan split or as Bryan permits
C41: Tenant 5 | H41: =G41*I41 -> 0 | N41: Lender | S41: KingSett | T41: KingSett
...

Sheet Buydown Calc
C2: Loan | D2: =+IF(Economics!I155=0,Economics!I64,Economics!I158) -> #N/A
C3: Max Rate | D3: =+IF(Economics!I165="",Economics!I71,Economics!I165) -> 0
C5: Buydown | D5: Duration | E5: Loan Rate | F5: PMT | H5: Month | I5: 1 | J5: =I5+1 -> 2 | K5: =J5+1 -> 3 | L5: =K5+1 -> 4 | M5: =L5+1 -> 5 | N5: =M5+1 -> 6 | O5: =N5+1 -> 7 | P5: =O5+1 -> 8 | Q5: =P5+1 -> 9 | ... EJ5: =EI5+1 -> 132
B6: 5yr | C6: =+IF(E6>$D$3,D6*(E6-$D$3)*$D$2,0) -> #N/A | D6: =IFERROR((NPV(((1+(E6-0.01%)/2)^(2/12)-1),$I20:$EJ20)-NPV(((1+(E6+0.01%)/2)^(2/12)-1),$I20:$EJ20))/2,"") -> 0 | E6: =+Economics!I239 -> 0.0331 | F6: =IFERROR(-PMT((1+E6/2)^(2/12)-1,Economics!$I$160* 12, 10000),-PMT((1+E6/2)^(2/12)-1,Economics!$I$69* 12, 10000)) -> #NUM!
B7: 10yr | C7: =+IF(E7>$D$3,D7*(E7-$D$3)*$D$2,0) -> #N/A | D7: =IFERROR((NPV(((1+(E7-0.01%)/2)^(2/12)-1),$I21:$EJ21)-NPV(((1+(E7+0.01%)/2)^(2/12)-1),$I21:$EJ21))/2,"") -> 0 | E7: =+Economics!J239 -> 0.0374 | F7: =IFERROR(-PMT((1+E7/2)^(2/12)-1,Economics!$I$160* 12, 10000),-PMT((1+E7/2)^(2/12)-1,Economics!$I$69* 12, 10000)) -> #NUM! | H7: Balance
H8: 5yr | I8: =IF(I$5=1,10000,H8-H16) -> 10000 | J8: =IF(J$5=1,10000,I8-I16) -> #NUM! | K8: =IF(K$5=1,10000,J8-J16) -> #NUM! | L8: =IF(L$5=1,10000,K8-K16) -> #NUM! | M8: =IF(M$5=1,10000,L8-L16) -> #NUM! | N8: =IF(N$5=1,10000,M8-M16) -> #NUM! | O8: =IF(O$5=1,10000,N8-N16) -> #NUM! | P8: =IF(P$5=1,10000,O8-O16) -> #NUM! | ... EJ8: =IF(EJ$5=1,10000,EI8-EI16) -> #NUM!
H9: 10yr | I9: =IF(I$5=1,10000,H9-H17) -> 10000 | J9: =IF(J$5=1,10000,I9-I17) -> #NUM! | K9: =IF(K$5=1,10000,J9-J17) -> #NUM! | L9: =IF(L$5=1,10000,K9-K17) -> #NUM! | M9: =IF(M$5=1,10000,L9-L17) -> #NUM! | N9: =IF(N$5=1,10000,M9-M17) -> #NUM! | O9: =IF(O$5=1,10000,N9-N17) -> #NUM! | P9: =IF(P$5=1,10000,O9-O17) -> #NUM! | ... EJ9: =IF(EJ$5=1,10000,EI9-EI17) -> #NUM!
H11: Interest
H12: 5yr | I12: =IFERROR(ROUND(((1+$E6/2)^(2/12)-1)*I8,2),"") -> 27.4 | J12: =IFERROR(ROUND(((1+$E6/2)^(2/12)-1)*J8,2),"") | K12: =IFERROR(ROUND(((1+$E6/2)^(2/12)-1)*K8,2),"") | L12: =IFERROR(ROUND(((1+$E6/2)^(2/12)-1)*L8,2),"") | M12: =IFERROR(ROUND(((1+$E6/2)^(2/12)-1)*M8,2),"") | N12: =IFERROR(ROUND(((1+$E6/2)^(2/12)-1)*N8,2),"") | O12: =IFERROR(ROUND(((1+$E6/2)^(2/12)-1)*O8,2),"") | P12: =IFERROR(ROUND(((1+$E6/2)^(2/12)-1)*P8,2),"") | ... EJ12: =IFERROR(ROUND(((1+$E6/2)^(2/12)-1)*EJ8,2),"")
H13: 10yr | I13: =IFERROR(ROUND(((1+$E7/2)^(2/12)-1)*I9,2),"") -> 30.93 | J13: =IFERROR(ROUND(((1+$E7/2)^(2/12)-1)*J9,2),"") | K13: =IFERROR(ROUND(((1+$E7/2)^(2/12)-1)*K9,2),"") | L13: =IFERROR(ROUND(((1+$E7/2)^(2/12)-1)*L9,2),"") | M13: =IFERROR(ROUND(((1+$E7/2)^(2/12)-1)*M9,2),"") | N13: =IFERROR(ROUND(((1+$E7/2)^(2/12)-1)*N9,2),"") | O13: =IFERROR(ROUND(((1+$E7/2)^(2/12)-1)*O9,2),"") | P13: =IFERROR(ROUND(((1+$E7/2)^(2/12)-1)*P9,2),"") | ... EJ13: =IFERROR(ROUND(((1+$E7/2)^(2/12)-1)*EJ9,2),"")
H15: Principal
H16: 5yr | I16: =IF(I$5<5*12,$F6-I12,IF(I$5=5*12,I8,0)) -> #NUM! | J16: =IF(J$5<5*12,$F6-J12,IF(J$5=5*12,J8,0)) -> #NUM! | K16: =IF(K$5<5*12,$F6-K12,IF(K$5=5*12,K8,0)) -> #NUM! | L16: =IF(L$5<5*12,$F6-L12,IF(L$5=5*12,L8,0)) -> #NUM! | M16: =IF(M$5<5*12,$F6-M12,IF(M$5=5*12,M8,0)) -> #NUM! | N16: =IF(N$5<5*12,$F6-N12,IF(N$5=5*12,N8,0)) -> #NUM! | O16: =IF(O$5<5*12,$F6-O12,IF(O$5=5*12,O8,0)) -> #NUM! | P16: =IF(P$5<5*12,$F6-P12,IF(P$5=5*12,P8,0)) -> #NUM! | ... EJ16: =IF(EJ$5<5*12,$F6-EJ12,IF(EJ$5=5*12,EJ8,0)) -> 0
H17: 10yr | I17: =IF(I$5<10*12,$F7-I13,IF(I$5=10*12,I9,0)) -> #NUM! | J17: =IF(J$5<10*12,$F7-J13,IF(J$5=10*12,J9,0)) -> #NUM! | K17: =IF(K$5<10*12,$F7-K13,IF(K$5=10*12,K9,0)) -> #NUM! | L17: =IF(L$5<10*12,$F7-L13,IF(L$5=10*12,L9,0)) -> #NUM! | M17: =IF(M$5<10*12,$F7-M13,IF(M$5=10*12,M9,0)) -> #NUM! | N17: =IF(N$5<10*12,$F7-N13,IF(N$5=10*12,N9,0)) -> #NUM! | O17: =IF(O$5<10*12,$F7-O13,IF(O$5=10*12,O9,0)) -> #NUM! | P17: =IF(P$5<10*12,$F7-P13,IF(P$5=10*12,P9,0)) -> #NUM! | ... EJ17: =IF(EJ$5<10*12,$F7-EJ13,IF(EJ$5=10*12,EJ9,0)) -> 0
H19: Total CF
H20: 5yr | I20: =IFERROR(I16+I12,"") | J20: =IFERROR(J16+J12,"") | K20: =IFERROR(K16+K12,"") | L20: =IFERROR(L16+L12,"") | M20: =IFERROR(M16+M12,"") | N20: =IFERROR(N16+N12,"") | O20: =IFERROR(O16+O12,"") | P20: =IFERROR(P16+P12,"") | ... EJ20: =IFERROR(EJ16+EJ12,"")
H21: 10yr | I21: =IFERROR(I17+I13,"") | J21: =IFERROR(J17+J13,"") | K21: =IFERROR(K17+K13,"") | L21: =IFERROR(L17+L13,"") | M21: =IFERROR(M17+M13,"") | N21: =IFERROR(N17+N13,"") | O21: =IFERROR(O17+O13,"") | P21: =IFERROR(P17+P13,"") | ... EJ21: =IFERROR(EJ17+EJ13,"")

Sheet ControlBackEnd
C2: <Region> | G2: Min Loan | H2: Servicing
C3: ON | G3: 0 | H3: =10*1.13 -> 11.3
C4: BC | G4: 2000000 | H4: =7*1.13 -> 7.91
C5: QC | G5: 5000000 | H5: =5*1.13 -> 5.65
C6: Atlantic | G6: 25000000 | H6: =4*1.13 -> 4.52
C7: Prairies & Territories | G7: 35000000 | H7: =3*1.13 -> 3.39
G8: 100000000 | H8: =2*1.13 -> 2.26
C9: <Housing Type>
C10: Standard Rental Housing
C11: Student
C12: SRO
C13: Retirement
C15: <Program>
C16: MLI Market
C17: MLI Select
C19: <EGI Test Met>
C20: Yes
C21: No
C23: <Select Frame>
... C91: <Term>
C92: 5
C93: 10
C95: <Premium Used>
C96: Pre-July 14, 2025
C97: Effective July 14, 2025

Sheet PremiumBackEnd
I1: Select vs Market Scenarios | L1: Select vs Market Scenarios | T1: Premium Credit
A2: Housing Type | B2: Program | C2: EGI Met | D2: Min LTV | E2: Max LTV | F2: Indicator | G2: Premium | I2: 5yr Market | L2: 10yr Market | P2: Increase | Q2: Pre June 19, 2023 Premiums | T2: Years since Previous Transaction | U2: Credit (% of Original Premium)
A3: Standard Rental Housing | B3: MLI Market | C3: Yes | D3: 0 | E3: 0.65 | F3: =IF(AND(Economics!$F$203=PremiumBackEnd!A3,Economics!$F$204=PremiumBackEnd!B3,Economics!$F$205=C3,$B$70<=PremiumBackEnd!E3,$B$70>=PremiumBackEnd!D3),"X","") -> #DIV/0! | G3: 0.026 | I3: =IF(AND(Economics!$F$203=PremiumBackEnd!A3,Economics!$AU$57=PremiumBackEnd!B3,Economics!$F$205=C3,Economics!$AU$74<=E3,Economics!$AU$74>=D3),"X","") | J3: =+PremiumBackEnd!G3 -> 0.026 | L3: =IF(AND(Economics!$F$203=PremiumBackEnd!A3,Economics!$AV$57=PremiumBackEnd!B3,Economics!$F$205=PremiumBackEnd!C3,Economics!$AV$74<=PremiumBackEnd!E3,Economics!$AV$74>=PremiumBackEnd!D3),"X","") | M3: =+PremiumBackEnd!G3 -> 0.026 | P3: =+G3-Q3 -> 0.0085 | Q3: 0.0175 | T3: 1 | U3: 0.75
A4: Standard Rental Housing | B4: MLI Market | C4: Yes | D4: =+E3+0.00001 -> 0.65001 | E4: 0.7 | F4: =IF(AND(Economics!$F$203=PremiumBackEnd!A4,Economics!$F$204=PremiumBackEnd!B4,Economics!$F$205=C4,$B$70<=PremiumBackEnd!E4,$B$70>=PremiumBackEnd!D4),"X","") -> #DIV/0! | G4: 0.0285 | I4: =IF(AND(Economics!$F$203=PremiumBackEnd!A4,Economics!$AU$57=PremiumBackEnd!B4,Economics!$F$205=PremiumBackEnd!C4,Economics!$AU$74<=PremiumBackEnd!E4,Economics!$AU$74>=PremiumBackEnd!D4),"X","") | J4: =+PremiumBackEnd!G4 -> 0.0285 | L4: =IF(AND(Economics!$F$203=PremiumBackEnd!A4,Economics!$AV$57=PremiumBackEnd!B4,Economics!$F$205=PremiumBackEnd!C4,Economics!$AV$74<=PremiumBackEnd!E4,Economics!$AV$74>=PremiumBackEnd!D4),"X","") | M4: =+PremiumBackEnd!G4 -> 0.0285 | P4: =+G4-Q4 -> 0.0085 | Q4: 0.02 | T4: 2 | U4: 0.7
A5: Standard Rental Housing | B5: MLI Market | C5: Yes | D5: =+E4+0.00001 -> 0.70001 | E5: 0.75 | F5: =IF(AND(Economics!$F$203=PremiumBackEnd!A5,Economics!$F$204=PremiumBackEnd!B5,Economics!$F$205=C5,$B$70<=PremiumBackEnd!E5,$B$70>=PremiumBackEnd!D5),"X","") -> #DIV/0! | G5: 0.0335 | I5: =IF(AND(Economics!$F$203=PremiumBackEnd!A5,Economics!$AU$57=PremiumBackEnd!B5,Economics!$F$205=PremiumBackEnd!C5,Economics!$AU$74<=PremiumBackEnd!E5,Economics!$AU$74>=PremiumBackEnd!D5),"X","") | J5: =+PremiumBackEnd!G5 -> 0.0335 | L5: =IF(AND(Economics!$F$203=PremiumBackEnd!A5,Economics!$AV$57=PremiumBackEnd!B5,Economics!$F$205=PremiumBackEnd!C5,Economics!$AV$74<=PremiumBackEnd!E5,Economics!$AV$74>=PremiumBackEnd!D5),"X","") | M5: =+PremiumBackEnd!G5 -> 0.0335 | P5: =+G5-Q5 -> 0.0085 | Q5: 0.025 | T5: 3 | U5: 0.6
A6: Standard Rental Housing | B6: MLI Market | C6: Yes | D6: =+E5+0.00001 -> 0.75001 | E6: 0.8 | F6: =IF(AND(Economics!$F$203=PremiumBackEnd!A6,Economics!$F$204=PremiumBackEnd!B6,Economics!$F$205=C6,$B$70<=PremiumBackEnd!E6,$B$70>=PremiumBackEnd!D6),"X","") -> #DIV/0! | G6: 0.0435 | I6: =IF(AND(Economics!$F$203=PremiumBackEnd!A6,Economics!$AU$57=PremiumBackEnd!B6,Economics!$F$205=PremiumBackEnd!C6,Economics!$AU$74<=PremiumBackEnd!E6,Economics!$AU$74>=PremiumBackEnd!D6),"X","") | J6: =+PremiumBackEnd!G6 -> 0.0435 | L6: =IF(AND(Economics!$F$203=PremiumBackEnd!A6,Economics!$AV$57=PremiumBackEnd!B6,Economics!$F$205=PremiumBackEnd!C6,Economics!$AV$74<=PremiumBackEnd!E6,Economics!$AV$74>=PremiumBackEnd!D6),"X","") | M6: =+PremiumBackEnd!G6 -> 0.0435 | P6: =+G6-Q6 -> 0.0085 | Q6: 0.035 | T6: 4 | U6: 0.5
A7: Standard Rental Housing | B7: MLI Market | C7: Yes | D7: =+E6+0.00001 -> 0.80001 | E7: 0.85 | F7: =IF(AND(Economics!$F$203=PremiumBackEnd!A7,Economics!$F$204=PremiumBackEnd!B7,Economics!$F$205=C7,$B$70<=PremiumBackEnd!E7,$B$70>=PremiumBackEnd!D7),"X","") -> #DIV/0! | G7: 0.0535 | I7: =IF(AND(Economics!$F$203=PremiumBackEnd!A7,Economics!$AU$57=PremiumBackEnd!B7,Economics!$F$205=PremiumBackEnd!C7,Economics!$AU$74<=PremiumBackEnd!E7,Economics!$AU$74>=PremiumBackEnd!D7),"X","") | J7: =+PremiumBackEnd!G7 -> 0.0535 | L7: =IF(AND(Economics!$F$203=PremiumBackEnd!A7,Economics!$AV$57=PremiumBackEnd!B7,Economics!$F$205=PremiumBackEnd!C7,Economics!$AV$74<=PremiumBackEnd!E7,Economics!$AV$74>=PremiumBackEnd!D7),"X","") | M7: =+PremiumBackEnd!G7 -> 0.0535 | P7: =+G7-Q7 -> 0.0085 | Q7: 0.045 | T7: 5 | U7: 0.4
T8: 6 | U8: 0.3
A9: Student | B9: MLI Market | C9: Yes | D9: 0 | E9: 0.65 | F9: =IF(AND(Economics!$F$203=PremiumBackEnd!A9,Economics!$F$204=PremiumBackEnd!B9,Economics!$F$205=C9,$B$70<=PremiumBackEnd!E9,$B$70>=PremiumBackEnd!D9),"X","") -> #DIV/0! | G9: 0.0335 | I9: =IF(AND(Economics!$F$203=PremiumBackEnd!A9,Economics!$AU$57=PremiumBackEnd!B9,Economics!$F$205=PremiumBackEnd!C9,Economics!$AU$74<=PremiumBackEnd!E9,Economics!$AU$74>=PremiumBackEnd!D9),"X","") | J9: =+PremiumBackEnd!G9 -> 0.0335 | L9: =IF(AND(Economics!$F$203=PremiumBackEnd!A9,Economics!$AV$57=PremiumBackEnd!B9,Economics!$F$205=PremiumBackEnd!C9,Economics!$AV$74<=PremiumBackEnd!E9,Economics!$AV$74>=PremiumBackEnd!D9),"X","") | M9: =+PremiumBackEnd!G9 -> 0.0335 | P9: =+G9-Q9 -> 0.0085 | Q9: 0.025 | T9: 7 | U9: 0.2
A10: Student | B10: MLI Market | C10: Yes | D10: =+E9+0.00001 -> 0.65001 | E10: 0.7 | F10: =IF(AND(Economics!$F$203=PremiumBackEnd!A10,Economics!$F$204=PremiumBackEnd!B10,Economics!$F$205=C10,$B$70<=PremiumBackEnd!E10,$B$70>=PremiumBackEnd!D10),"X","") -> #DIV/0! | G10: 0.0385 | I10: =IF(AND(Economics!$F$203=PremiumBackEnd!A10,Economics!$AU$57=PremiumBackEnd!B10,Economics!$F$205=PremiumBackEnd!C10,Economics!$AU$74<=PremiumBackEnd!E10,Economics!$AU$74>=PremiumBackEnd!D10),"X","") | J10: =+PremiumBackEnd!G10 -> 0.0385 | L10: =IF(AND(Economics!$F$203=PremiumBackEnd!A10,Economics!$AV$57=PremiumBackEnd!B10,Economics!$F$205=PremiumBackEnd!C10,Economics!$AV$74<=PremiumBackEnd!E10,Economics!$AV$74>=PremiumBackEnd!D10),"X","") | M10: =+PremiumBackEnd!G10 -> 0.0385 | P10: =+G10-Q10 -> 0.0085 | Q10: 0.03
A11: Student | B11: MLI Market | C11: Yes | D11: =+E10+0.00001 -> 0.70001 | E11: 0.75 | F11: =IF(AND(Economics!$F$203=PremiumBackEnd!A11,Economics!$F$204=PremiumBackEnd!B11,Economics!$F$205=C11,$B$70<=PremiumBackEnd!E11,$B$70>=PremiumBackEnd!D11),"X","") -> #DIV/0! | G11: 0.0435 | I11: =IF(AND(Economics!$F$203=PremiumBackEnd!A11,Economics!$AU$57=PremiumBackEnd!B11,Economics!$F$205=PremiumBackEnd!C11,Economics!$AU$74<=PremiumBackEnd!E11,Economics!$AU$74>=PremiumBackEnd!D11),"X","") | J11: =+PremiumBackEnd!G11 -> 0.0435 | L11: =IF(AND(Economics!$F$203=PremiumBackEnd!A11,Economics!$AV$57=PremiumBackEnd!B11,Economics!$F$205=PremiumBackEnd!C11,Economics!$AV$74<=PremiumBackEnd!E11,Economics!$AV$74>=PremiumBackEnd!D11),"X","") | M11: =+PremiumBackEnd!G11 -> 0.0435 | P11: =+G11-Q11 -> 0.0085 | Q11: 0.035
A12: Student | B12: MLI Market | C12: Yes | D12: =+E11+0.00001 -> 0.75001 | E12: 0.8 | F12: =IF(AND(Economics!$F$203=PremiumBackEnd!A12,Economics!$F$204=PremiumBackEnd!B12,Economics!$F$205=C12,$B$70<=PremiumBackEnd!E12,$B$70>=PremiumBackEnd!D12),"X","") -> #DIV/0! | G12: 0.051 | I12: =IF(AND(Economics!$F$203=PremiumBackEnd!A12,Economics!$AU$57=PremiumBackEnd!B12,Economics!$F$205=PremiumBackEnd!C12,Economics!$AU$74<=PremiumBackEnd!E12,Economics!$AU$74>=PremiumBackEnd!D12),"X","") | J12: =+PremiumBackEnd!G12 -> 0.051 | L12: =IF(AND(Economics!$F$203=PremiumBackEnd!A12,Economics!$AV$57=PremiumBackEnd!B12,Economics!$F$205=PremiumBackEnd!C12,Economics!$AV$74<=PremiumBackEnd!E12,Economics!$AV$74>=PremiumBackEnd!D12),"X","") | M12: =+PremiumBackEnd!G12 -> 0.051 | P12: =+G12-Q12 -> 0.0085 | Q12: 0.0425
A13: Student | B13: MLI Market | C13: Yes | D13: =+E12+0.00001 -> 0.80001 | E13: 0.85 | F13: =IF(AND(Economics!$F$203=PremiumBackEnd!A13,Economics!$F$204=PremiumBackEnd!B13,Economics!$F$205=C13,$B$70<=PremiumBackEnd!E13,$B$70>=PremiumBackEnd!D13),"X","") -> #DIV/0! | G13: 0.061 | I13: =IF(AND(Economics!$F$203=PremiumBackEnd!A13,Economics!$AU$57=PremiumBackEnd!B13,Economics!$F$205=PremiumBackEnd!C13,Economics!$AU$74<=PremiumBackEnd!E13,Economics!$AU$74>=PremiumBackEnd!D13),"X","") | J13: =+PremiumBackEnd!G13 -> 0.061 | L13: =IF(AND(Economics!$F$203=PremiumBackEnd!A13,Economics!$AV$57=PremiumBackEnd!B13,Economics!$F$205=PremiumBackEnd!C13,Economics!$AV$74<=PremiumBackEnd!E13,Economics!$AV$74>=PremiumBackEnd!D13),"X","") | M13: =+PremiumBackEnd!G13 -> 0.061 | P13: =+G13-Q13 -> 0.0085 | Q13: 0.0525
A15: SRO | B15: MLI Market | C15: Yes | D15: 0 | E15: 0.65 | F15: =IF(AND(Economics!$F$203=PremiumBackEnd!A15,Economics!$F$204=PremiumBackEnd!B15,Economics!$F$205=C15,$B$70<=PremiumBackEnd!E15,$B$70>=PremiumBackEnd!D15),"X","") -> #DIV/0! | G15: 0.0335 | I15: =IF(AND(Economics!$F$203=PremiumBackEnd!A15,Economics!$AU$57=PremiumBackEnd!B15,Economics!$F$205=PremiumBackEnd!C15,Economics!$AU$74<=PremiumBackEnd!E15,Economics!$AU$74>=PremiumBackEnd!D15),"X","") | J15: =+PremiumBackEnd!G15 -> 0.0335 | L15: =IF(AND(Economics!$F$203=PremiumBackEnd!A15,Economics!$AV$57=PremiumBackEnd!B15,Economics!$F$205=PremiumBackEnd!C15,Economics!$AV$74<=PremiumBackEnd!E15,Economics!$AV$74>=PremiumBackEnd!D15),"X","") | M15: =+PremiumBackEnd!G15 -> 0.0335 | P15: =+G15-Q15 -> 0.0085 | Q15: 0.025
A16: SRO | B16: MLI Market | C16: Yes | D16: =+E15+0.00001 -> 0.65001 | E16: 0.7 | F16: =IF(AND(Economics!$F$203=PremiumBackEnd!A16,Economics!$F$204=PremiumBackEnd!B16,Economics!$F$205=C16,$B$70<=PremiumBackEnd!E16,$B$70>=PremiumBackEnd!D16),"X","") -> #DIV/0! | G16: 0.0385 | I16: =IF(AND(Economics!$F$203=PremiumBackEnd!A16,Economics!$AU$57=PremiumBackEnd!B16,Economics!$F$205=PremiumBackEnd!C16,Economics!$AU$74<=PremiumBackEnd!E16,Economics!$AU$74>=PremiumBackEnd!D16),"X","") | J16: =+PremiumBackEnd!G16 -> 0.0385 | L16: =IF(AND(Economics!$F$203=PremiumBackEnd!A16,Economics!$AV$57=PremiumBackEnd!B16,Economics!$F$205=PremiumBackEnd!C16,Economics!$AV$74<=PremiumBackEnd!E16,Economics!$AV$74>=PremiumBackEnd!D16),"X","") | M16: =+PremiumBackEnd!G16 -> 0.0385 | P16: =+G16-Q16 -> 0.0085 | Q16: 0.03
A17: SRO | B17: MLI Market | C17: Yes | D17: =+E16+0.00001 -> 0.70001 | E17: 0.75 | F17: =IF(AND(Economics!$F$203=PremiumBackEnd!A17,Economics!$F$204=PremiumBackEnd!B17,Economics!$F$205=C17,$B$70<=PremiumBackEnd!E17,$B$70>=PremiumBackEnd!D17),"X","") -> #DIV/0! | G17: 0.0435 | I17: =IF(AND(Economics!$F$203=PremiumBackEnd!A17,Economics!$AU$57=PremiumBackEnd!B17,Economics!$F$205=PremiumBackEnd!C17,Economics!$AU$74<=PremiumBackEnd!E17,Economics!$AU$74>=PremiumBackEnd!D17),"X","") | J17: =+PremiumBackEnd!G17 -> 0.0435 | L17: =IF(AND(Economics!$F$203=PremiumBackEnd!A17,Economics!$AV$57=PremiumBackEnd!B17,Economics!$F$205=PremiumBackEnd!C17,Economics!$AV$74<=PremiumBackEnd!E17,Economics!$AV$74>=PremiumBackEnd!D17),"X","") | M17: =+PremiumBackEnd!G17 -> 0.0435 | P17: =+G17-Q17 -> 0.0085 | Q17: 0.035
A18: SRO | B18: MLI Market | C18: Yes | D18: =+E17+0.00001 -> 0.75001 | E18: 0.8 | F18: =IF(AND(Economics!$F$203=PremiumBackEnd!A18,Economics!$F$204=PremiumBackEnd!B18,Economics!$F$205=C18,$B$70<=PremiumBackEnd!E18,$B$70>=PremiumBackEnd!D18),"X","") -> #DIV/0! | G18: 0.051 | I18: =IF(AND(Economics!$F$203=PremiumBackEnd!A18,Economics!$AU$57=PremiumBackEnd!B18,Economics!$F$205=PremiumBackEnd!C18,Economics!$AU$74<=PremiumBackEnd!E18,Economics!$AU$74>=PremiumBackEnd!D18),"X","") | J18: =+PremiumBackEnd!G18 -> 0.051 | L18: =IF(AND(Economics!$F$203=PremiumBackEnd!A18,Economics!$AV$57=PremiumBackEnd!B18,Economics!$F$205=PremiumBackEnd!C18,Economics!$AV$74<=PremiumBackEnd!E18,Economics!$AV$74>=PremiumBackEnd!D18),"X","") | M18: =+PremiumBackEnd!G18 -> 0.051 | P18: =+G18-Q18 -> 0.0085 | Q18: 0.0425
A19: SRO | B19: MLI Market | C19: Yes | D19: =+E18+0.00001 -> 0.80001 | E19: 0.85 | F19: =IF(AND(Economics!$F$203=PremiumBackEnd!A19,Economics!$F$204=PremiumBackEnd!B19,Economics!$F$205=C19,$B$70<=PremiumBackEnd!E19,$B$70>=PremiumBackEnd!D19),"X","") -> #DIV/0! | G19: 0.061 | I19: =IF(AND(Economics!$F$203=PremiumBackEnd!A19,Economics!$AU$57=PremiumBackEnd!B19,Economics!$F$205=PremiumBackEnd!C19,Economics!$AU$74<=PremiumBackEnd!E19,Economics!$AU$74>=PremiumBackEnd!D19),"X","") | J19: =+PremiumBackEnd!G19 -> 0.061 | L19: =IF(AND(Economics!$F$203=PremiumBackEnd!A19,Economics!$AV$57=PremiumBackEnd!B19,Economics!$F$205=PremiumBackEnd!C19,Economics!$AV$74<=PremiumBackEnd!E19,Economics!$AV$74>=PremiumBackEnd!D19),"X","") | M19: =+PremiumBackEnd!G19 -> 0.061 | P19: =+G19-Q19 -> 0.0085 | Q19: 0.0525
A21: Retirement | B21: MLI Market | C21: Yes | D21: 0 | E21: 0.65 | F21: =IF(AND(Economics!$F$203=PremiumBackEnd!A21,Economics!$F$204=PremiumBackEnd!B21,Economics!$F$205=C21,$B$70<=PremiumBackEnd!E21,$B$70>=PremiumBackEnd!D21),"X","") -> #DIV/0! | G21: 0.041 | I21: =IF(AND(Economics!$F$203=PremiumBackEnd!A21,Economics!$AU$57=PremiumBackEnd!B21,Economics!$F$205=PremiumBackEnd!C21,Economics!$AU$74<=PremiumBackEnd!E21,Economics!$AU$74>=PremiumBackEnd!D21),"X","") | J21: =+PremiumBackEnd!G21 -> 0.041 | L21: =IF(AND(Economics!$F$203=PremiumBackEnd!A21,Economics!$AV$57=PremiumBackEnd!B21,Economics!$F$205=PremiumBackEnd!C21,Economics!$AV$74<=PremiumBackEnd!E21,Economics!$AV$74>=PremiumBackEnd!D21),"X","") | M21: =+PremiumBackEnd!G21 -> 0.041 | P21: =+G21-Q21 -> 0.0085 | Q21: 0.0325
A22: Retirement | B22: MLI Market | C22: Yes | D22: =+E21+0.00001 -> 0.65001 | E22: 0.7 | F22: =IF(AND(Economics!$F$203=PremiumBackEnd!A22,Economics!$F$204=PremiumBackEnd!B22,Economics!$F$205=C22,$B$70<=PremiumBackEnd!E22,$B$70>=PremiumBackEnd!D22),"X","") -> #DIV/0! | G22: 0.046 | I22: =IF(AND(Economics!$F$203=PremiumBackEnd!A22,Economics!$AU$57=PremiumBackEnd!B22,Economics!$F$205=PremiumBackEnd!C22,Economics!$AU$74<=PremiumBackEnd!E22,Economics!$AU$74>=PremiumBackEnd!D22),"X","") | J22: =+PremiumBackEnd!G22 -> 0.046 | L22: =IF(AND(Economics!$F$203=PremiumBackEnd!A22,Economics!$AV$57=PremiumBackEnd!B22,Economics!$F$205=PremiumBackEnd!C22,Economics!$AV$74<=PremiumBackEnd!E22,Economics!$AV$74>=PremiumBackEnd!D22),"X","") | M22: =+PremiumBackEnd!G22 -> 0.046 | P22: =+G22-Q22 -> 0.0085 | Q22: 0.0375
A23: Retirement | B23: MLI Market | C23: Yes | D23: =+E22+0.00001 -> 0.70001 | E23: 0.75 | F23: =IF(AND(Economics!$F$203=PremiumBackEnd!A23,Economics!$F$204=PremiumBackEnd!B23,Economics!$F$205=C23,$B$70<=PremiumBackEnd!E23,$B$70>=PremiumBackEnd!D23),"X","") -> #DIV/0! | G23: 0.051 | I23: =IF(AND(Economics!$F$203=PremiumBackEnd!A23,Economics!$AU$57=PremiumBackEnd!B23,Economics!$F$205=PremiumBackEnd!C23,Economics!$AU$74<=PremiumBackEnd!E23,Economics!$AU$74>=PremiumBackEnd!D23),"X","") | J23: =+PremiumBackEnd!G23 -> 0.051 | L23: =IF(AND(Economics!$F$203=PremiumBackEnd!A23,Economics!$AV$57=PremiumBackEnd!B23,Economics!$F$205=PremiumBackEnd!C23,Economics!$AV$74<=PremiumBackEnd!E23,Economics!$AV$74>=PremiumBackEnd!D23),"X","") | M23: =+PremiumBackEnd!G23 -> 0.051 | P23: =+G23-Q23 -> 0.0085 | Q23: 0.0425
A24: Retirement | B24: MLI Market | C24: Yes | D24: =+E23+0.00001 -> 0.75001 | E24: 0.8 | F24: =IF(AND(Economics!$F$203=PremiumBackEnd!A24,Economics!$F$204=PremiumBackEnd!B24,Economics!$F$205=C24,$B$70<=PremiumBackEnd!E24,$B$70>=PremiumBackEnd!D24),"X","") -> #DIV/0! | G24: 0.0585 | I24: =IF(AND(Economics!$F$203=PremiumBackEnd!A24,Economics!$AU$57=PremiumBackEnd!B24,Economics!$F$205=PremiumBackEnd!C24,Economics!$AU$74<=PremiumBackEnd!E24,Economics!$AU$74>=PremiumBackEnd!D24),"X","") | J24: =+PremiumBackEnd!G24 -> 0.0585 | L24: =IF(AND(Economics!$F$203=PremiumBackEnd!A24,Economics!$AV$57=PremiumBackEnd!B24,Economics!$F$205=PremiumBackEnd!C24,Economics!$AV$74<=PremiumBackEnd!E24,Economics!$AV$74>=PremiumBackEnd!D24),"X","") | M24: =+PremiumBackEnd!G24 -> 0.0585 | P24: =+G24-Q24 -> 0.0085 | Q24: 0.05
A25: Retirement | B25: MLI Market | C25: Yes | D25: =+E24+0.00001 -> 0.80001 | E25: 0.85 | F25: =IF(AND(Economics!$F$203=PremiumBackEnd!A25,Economics!$F$204=PremiumBackEnd!B25,Economics!$F$205=C25,$B$70<=PremiumBackEnd!E25,$B$70>=PremiumBackEnd!D25),"X","") -> #DIV/0! | G25: 0.066 | I25: =IF(AND(Economics!$F$203=PremiumBackEnd!A25,Economics!$AU$57=PremiumBackEnd!B25,Economics!$F$205=PremiumBackEnd!C25,Economics!$AU$74<=PremiumBackEnd!E25,Economics!$AU$74>=PremiumBackEnd!D25),"X","") | J25: =+PremiumBackEnd!G25 -> 0.066 | L25: =IF(AND(Economics!$F$203=PremiumBackEnd!A25,Economics!$AV$57=PremiumBackEnd!B25,Economics!$F$205=PremiumBackEnd!C25,Economics!$AV$74<=PremiumBackEnd!E25,Economics!$AV$74>=PremiumBackEnd!D25),"X","") | M25: =+PremiumBackEnd!G25 -> 0.066 | P25: =+G25-Q25 -> 0.0085 | Q25: 0.0575
A27: Standard Rental Housing | B27: MLI Market | C27: No | D27: 0 | E27: 0.65 | F27: =IF(AND(Economics!$F$203=PremiumBackEnd!A27,Economics!$F$204=PremiumBackEnd!B27,Economics!$F$205=C27,$B$70<=PremiumBackEnd!E27,$B$70>=PremiumBackEnd!D27),"X","") -> #DIV/0! | G27: 0.0325 | I27: =IF(AND(Economics!$F$203=PremiumBackEnd!A27,Economics!$AU$57=PremiumBackEnd!B27,Economics!$F$205=PremiumBackEnd!C27,Economics!$AU$74<=PremiumBackEnd!E27,Economics!$AU$74>=PremiumBackEnd!D27),"X","") | J27: =+PremiumBackEnd!G27 -> 0.0325 | L27: =IF(AND(Economics!$F$203=PremiumBackEnd!A27,Economics!$AV$57=PremiumBackEnd!B27,Economics!$F$205=PremiumBackEnd!C27,Economics!$AV$74<=PremiumBackEnd!E27,Economics!$AV$74>=PremiumBackEnd!D27),"X","") | M27: =+PremiumBackEnd!G27 -> 0.0325 | P27: =+G27-Q27 -> 0.0075 | Q27: 0.025
A28: Standard Rental Housing | B28: MLI Market | C28: No | D28: =+E27+0.00001 -> 0.65001 | E28: 0.7 | F28: =IF(AND(Economics!$F$203=PremiumBackEnd!A28,Economics!$F$204=PremiumBackEnd!B28,Economics!$F$205=C28,$B$70<=PremiumBackEnd!E28,$B$70>=PremiumBackEnd!D28),"X","") -> #DIV/0! | G28: 0.0375 | I28: =IF(AND(Economics!$F$203=PremiumBackEnd!A28,Economics!$AU$57=PremiumBackEnd!B28,Economics!$F$205=PremiumBackEnd!C28,Economics!$AU$74<=PremiumBackEnd!E28,Economics!$AU$74>=PremiumBackEnd!D28),"X","") | J28: =+PremiumBackEnd!G28 -> 0.0375 | L28: =IF(AND(Economics!$F$203=PremiumBackEnd!A28,Economics!$AV$57=PremiumBackEnd!B28,Economics!$F$205=PremiumBackEnd!C28,Economics!$AV$74<=PremiumBackEnd!E28,Economics!$AV$74>=PremiumBackEnd!D28),"X","") | M28: =+PremiumBackEnd!G28 -> 0.0375 | P28: =+G28-Q28 -> 0.0075 | Q28: 0.03
A29: Standard Rental Housing | B29: MLI Market | C29: No | D29: =+E28+0.00001 -> 0.70001 | E29: 0.75 | F29: =IF(AND(Economics!$F$203=PremiumBackEnd!A29,Economics!$F$204=PremiumBackEnd!B29,Economics!$F$205=C29,$B$70<=PremiumBackEnd!E29,$B$70>=PremiumBackEnd!D29),"X","") -> #DIV/0! | G29: 0.0425 | I29: =IF(AND(Economics!$F$203=PremiumBackEnd!A29,Economics!$AU$57=PremiumBackEnd!B29,Economics!$F$205=PremiumBackEnd!C29,Economics!$AU$74<=PremiumBackEnd!E29,Economics!$AU$74>=PremiumBackEnd!D29),"X","") | J29: =+PremiumBackEnd!G29 -> 0.0425 | L29: =IF(AND(Economics!$F$203=PremiumBackEnd!A29,Economics!$AV$57=PremiumBackEnd!B29,Economics!$F$205=PremiumBackEnd!C29,Economics!$AV$74<=PremiumBackEnd!E29,Economics!$AV$74>=PremiumBackEnd!D29),"X","") | M29: =+PremiumBackEnd!G29 -> 0.0425 | P29: =+G29-Q29 -> 0.0075 | Q29: 0.035
A30: Standard Rental Housing | B30: MLI Market | C30: No | D30: =+E29+0.00001 -> 0.75001 | E30: 0.8 | F30: =IF(AND(Economics!$F$203=PremiumBackEnd!A30,Economics!$F$204=PremiumBackEnd!B30,Economics!$F$205=C30,$B$70<=PremiumBackEnd!E30,$B$70>=PremiumBackEnd!D30),"X","") -> #DIV/0! | G30: 0.05 | I30: =IF(AND(Economics!$F$203=PremiumBackEnd!A30,Economics!$AU$57=PremiumBackEnd!B30,Economics!$F$205=PremiumBackEnd!C30,Economics!$AU$74<=PremiumBackEnd!E30,Economics!$AU$74>=PremiumBackEnd!D30),"X","") | J30: =+PremiumBackEnd!G30 -> 0.05 | L30: =IF(AND(Economics!$F$203=PremiumBackEnd!A30,Economics!$AV$57=PremiumBackEnd!B30,Economics!$F$205=PremiumBackEnd!C30,Economics!$AV$74<=PremiumBackEnd!E30,Economics!$AV$74>=PremiumBackEnd!D30),"X","") | M30: =+PremiumBackEnd!G30 -> 0.05 | P30: =+G30-Q30 -> 0.0075 | Q30: 0.0425
A31: Standard Rental Housing | B31: MLI Market | C31: No | D31: =+E30+0.00001 -> 0.80001 | E31: 0.85 | F31: =IF(AND(Economics!$F$203=PremiumBackEnd!A31,Economics!$F$204=PremiumBackEnd!B31,Economics!$F$205=C31,$B$70<=PremiumBackEnd!E31,$B$70>=PremiumBackEnd!D31),"X","") -> #DIV/0! | G31: 0.06 | I31: =IF(AND(Economics!$F$203=PremiumBackEnd!A31,Economics!$AU$57=PremiumBackEnd!B31,Economics!$F$205=PremiumBackEnd!C31,Economics!$AU$74<=PremiumBackEnd!E31,Economics!$AU$74>=PremiumBackEnd!D31),"X","") | J31: =+PremiumBackEnd!G31 -> 0.06 | L31: =IF(AND(Economics!$F$203=PremiumBackEnd!A31,Economics!$AV$57=PremiumBackEnd!B31,Economics!$F$205=PremiumBackEnd!C31,Economics!$AV$74<=PremiumBackEnd!E31,Economics!$AV$74>=PremiumBackEnd!D31),"X","") | M31: =+PremiumBackEnd!G31 -> 0.06 | P31: =+G31-Q31 -> 0.0075 | Q31: 0.0525
A33: Student | B33: MLI Market | C33: No | D33: 0 | E33: 0.65 | F33: =IF(AND(Economics!$F$203=PremiumBackEnd!A33,Economics!$F$204=PremiumBackEnd!B33,Economics!$F$205=C33,$B$70<=PremiumBackEnd!E33,$B$70>=PremiumBackEnd!D33),"X","") -> #DIV/0! | G33: 0.04 | I33: =IF(AND(Economics!$F$203=PremiumBackEnd!A33,Economics!$AU$57=PremiumBackEnd!B33,Economics!$F$205=PremiumBackEnd!C33,Economics!$AU$74<=PremiumBackEnd!E33,Economics!$AU$74>=PremiumBackEnd!D33),"X","") | J33: =+PremiumBackEnd!G33 -> 0.04 | L33: =IF(AND(Economics!$F$203=PremiumBackEnd!A33,Economics!$AV$57=PremiumBackEnd!B33,Economics!$F$205=PremiumBackEnd!C33,Economics!$AV$74<=PremiumBackEnd!E33,Economics!$AV$74>=PremiumBackEnd!D33),"X","") | M33: =+PremiumBackEnd!G33 -> 0.04 | P33: =+G33-Q33 -> 0.0075 | Q33: 0.0325
A34: Student | B34: MLI Market | C34: No | D34: =+E33+0.00001 -> 0.65001 | E34: 0.7 | F34: =IF(AND(Economics!$F$203=PremiumBackEnd!A34,Economics!$F$204=PremiumBackEnd!B34,Economics!$F$205=C34,$B$70<=PremiumBackEnd!E34,$B$70>=PremiumBackEnd!D34),"X","") -> #DIV/0! | G34: 0.045 | I34: =IF(AND(Economics!$F$203=PremiumBackEnd!A34,Economics!$AU$57=PremiumBackEnd!B34,Economics!$F$205=PremiumBackEnd!C34,Economics!$AU$74<=PremiumBackEnd!E34,Economics!$AU$74>=PremiumBackEnd!D34),"X","") | J34: =+PremiumBackEnd!G34 -> 0.045 | L34: =IF(AND(Economics!$F$203=PremiumBackEnd!A34,Economics!$AV$57=PremiumBackEnd!B34,Economics!$F$205=PremiumBackEnd!C34,Economics!$AV$74<=PremiumBackEnd!E34,Economics!$AV$74>=PremiumBackEnd!D34),"X","") | M34: =+PremiumBackEnd!G34 -> 0.045 | P34: =+G34-Q34 -> 0.0075 | Q34: 0.0375
